<?xml version='1.0'?>

<robot name="my_robot" xmlns:xacro="http://www.ros.org/wiki/xacro">

<xacro:include filename="$(find my_robot)/urdf/my_robot.gazebo" />

<!-- Using materials file for Rvis colors-->
<xacro:include filename="$(find my_robot)/urdf/my_robot_materials.xacro" />

  <!--Empty link to connect to whole robot -->
  <link name="robot_footprint"></link>

  <joint name="robot_footprint_joint" type="fixed">
    <origin xyz="0 0 0" rpy="0 0 0"/>
    <parent link="robot_footprint" />
    <child link="chassis" />
  </joint>

  <!-- Robot chassis-->
  <link name="chassis">

    <pose>0 0 0.1 0 0 0</pose>

    <inertial>
       <mass value="15.0" />
       <origin xyz="0.0 0 0 " rpy=" 0 0 0"/>

       <inertia
          ixx="0.1" ixy="0" ixz="0"
          iyy="0.1" iyz="0" izz="0.1"
       />

    </inertial>

    <collision name="chassis_collision">
       <origin xyz="0 0 0" rpy="0 0 0"/>
       <geometry>
         <box size=".3 .2 .2" />
       </geometry>
    </collision>

    <visual name="chassis_visual">
       <origin xyz="0 0 0" rpy="0 0 0"/>
       <geometry>
         <box size=".3 .2 .2" />
       </geometry>
       <material name="yellow" />
    </visual>

   <collision name='back_caster_collision'>
      <origin xyz="-0.1 0 -0.09" rpy=" 0 0 0"/>
      <geometry>
        <sphere radius="0.0499"/>
      </geometry>
    </collision>

    <visual name='back_caster_visual'>
      <origin xyz="-0.1 0 -0.09" rpy=" 0 0 0"/>
      <geometry>
        <sphere radius="0.05"/>
      </geometry>
      <material name="yellow" />
    </visual>

    <collision name='front_caster_collision'>
      <origin xyz="0.1 0 -0.09" rpy=" 0 0 0"/>
      <geometry>
        <sphere radius="0.0499"/>
      </geometry>
    </collision>

    <visual name='front_caster_visual'>
      <origin xyz="0.1 0 -0.09" rpy=" 0 0 0"/>
      <geometry>
        <sphere radius="0.05"/>
      </geometry>
      <material name="yellow" />
    </visual>


  </link>

  <!-- Left wheel -->
  <link name="left_wheel">

    <inertial>
       <mass value="5.0" />
       <origin xyz="0.0 0 0 " rpy=" 0 1.5707 1.5707"/>

       <inertia
          ixx="0.1" ixy="0" ixz="0"
          iyy="0.1" iyz="0" izz="0.1"
       />

    </inertial>
    <collision name="left_wheel_collision">
       <origin xyz="0 0 0" rpy="0 1.5707 1.5707"/>
       <geometry>
         <cylinder radius="0.09" length="0.07"/>
       </geometry>
    </collision>

    <visual name="left_wheel_visual">
       <origin xyz="0 0 0" rpy="0 1.5707 1.5707"/>
       <geometry>
         <cylinder radius="0.09" length="0.07" />
       </geometry>
       <material name="purple" />
    </visual>


  </link>

  <!-- Joint to connect left wheel to chassis -->
  <joint type="continuous" name="left_wheel_hinge">
    <origin xyz="0 0.14 -0.05" rpy="0 0 0"/>
    <child link="left_wheel"/>
    <parent link="chassis"/>
    <axis xyz="0 1 0" rpy="0 0 0"/>
    <limit effort="10000" velocity="1000"/>
    <dynamics damping="1.0" friction="1.0"/>
  </joint>

<!-- Right wheel -->
  <link name="right_wheel">

    <inertial>
       <mass value="5.0" />
       <origin xyz="0.0 0 0 " rpy=" 0 1.5707 1.5707"/>

       <inertia
          ixx="0.1" ixy="0" ixz="0"
          iyy="0.1" iyz="0" izz="0.1"
       />

    </inertial>
    <collision name="right_wheel_collision">
       <origin xyz="0 0 0" rpy="0 1.5707 1.5707"/>
       <geometry>
         <cylinder radius="0.09" length="0.07"/>
       </geometry>
    </collision>

    <visual name="right_wheel_visual">
       <origin xyz="0 0 0" rpy="0 1.5707 1.5707"/>
       <geometry>
         <cylinder radius="0.09" length="0.07" />
       </geometry>
       <material name="purple" />
    </visual>


  </link>

  <!-- Joint to connect right wheel to chassis -->
  <joint type="continuous" name="right_wheel_hinge">
    <origin xyz="0 -0.14 -0.05" rpy="0 0 0"/>
    <child link="right_wheel"/>
    <parent link="chassis"/>
    <axis xyz="0 1 0" rpy="0 0 0"/>
    <limit effort="10000" velocity="1000"/>
    <dynamics damping="1.0" friction="1.0"/>
  </joint>

  <!-- Camera -->
  <link name="camera">
    <inertial>
       <mass value="0.1" />
       <origin xyz="0.0 0 0 " rpy=" 0 0 0"/>

       <inertia
         ixx="1e-6" ixy="0" ixz="0" iyy="1e-6" iyz="0" izz="1e-6"
       />

    </inertial>

    <collision name="camera_collision">
       <origin xyz="0 0 0" rpy="0 0 0"/>
       <geometry>
         <box size="0.05 0.05 0.05"/>
       </geometry>
    </collision>

    <visual name="camera_visual">
       <origin xyz="0 0 0" rpy="0 0 0"/>
       <geometry>
         <box size="0.05 0.05 0.05" />
       </geometry>
       <material name="purple" />
    </visual>

    <box_inertia sizeX="0.05" sizeY="0.05" sizeZ="0.05" mass="0.1">
      <origin xyz="0.0 0.0 0.0" rpy="0 0 0" />
    </box_inertia>

  </link>

  <!-- Fixed joint to connect camera to robot-->
  <joint type="fixed" name="camera_joint">
    <origin xyz="0.15 0 -0.02" rpy="0 0 0"/>
    <child link="camera"/>
    <parent link="chassis"/>
    <axis xyz="0 1 0" rpy="0 0 0"/>

  </joint>


  <!-- Lidar sensor-->
  <link name="hokuyo">

    <inertial>
       <mass value= "1e-5"/>
       <origin xyz="0.0 0 0 " rpy=" 0 0 0"/>

       <inertia
          ixx="1e-6" ixy="0" ixz="0" iyy="1e-6" iyz="0" izz="1e-6"
       />

    </inertial>

    <collision name="hokuyo_collision">
       <origin xyz="0 0 0" rpy="0 0 0"/>
       <geometry>
         <box size="0.1 0.1 0.1"/>
       </geometry>
    </collision>

    <visual name="hokuyo_visual">
       <origin xyz="0 0 0" rpy="0 0 0"/>
       <geometry>
         <mesh filename="package://my_robot/meshes/hokuyo.dae" />
       </geometry>
    </visual>

  </link>


  <!-- Fixed joint to connect lidar sensor to robot-->
   <joint type="fixed" name="hokuyo_joint">
    <origin xyz="0.07 0 .13" rpy="0 0 0"/>
    <child link="hokuyo"/>
    <parent link="chassis"/>
    <axis xyz="0 1 0" rpy="0 0 0"/>

  </joint>

  <!-- Left eye-->
  <link name="left_eye">

    <collision name="left_eye_collision">
       <origin xyz="0 0 0" rpy="1.5707 0 0"/>
       <geometry>
         <cylinder radius="0.025" length="0.015"/>
       </geometry>
    </collision>

    <visual name="left_eye_visual">
       <origin xyz="0 0 0" rpy="0 1.5707 0"/>
       <geometry>
         <cylinder radius="0.025" length="0.015"/>
       </geometry>
       <material name="purple" />
    </visual>
  </link>

 <!-- Fixed joint to connect left eye to robot-->
  <joint type="fixed" name="left_eye_joint">
    <origin xyz="0.15 0.05 0.05" rpy="0 0 0"/>
    <child link="left_eye"/>
    <parent link="chassis"/>
    <axis xyz="0 1 0" rpy="0 0 0"/>

  </joint>

  <!-- Right eye-->
  <link name="right_eye">

    <collision name="right_eye_collision">
       <origin xyz="0 0 0" rpy="1.5707 0 0"/>
       <geometry>
         <cylinder radius="0.025" length="0.015"/>
       </geometry>
    </collision>

    <visual name="right_eye_visual">
       <origin xyz="0 0 0" rpy="0 1.5707 0"/>
       <geometry>
         <cylinder radius="0.025" length="0.015"/>
       </geometry>
       <material name="purple" />
    </visual>
  </link>

 <!-- Fixed joint to connect right eye to robot-->
  <joint type="fixed" name="right_eye_joint">
    <origin xyz="0.15 -0.05 0.05" rpy="0 0 0"/>
    <child link="right_eye"/>
    <parent link="chassis"/>
    <axis xyz="0 1 0" rpy="0 0 0"/>

  </joint>

  

</robot>
    
